<?xml version="1.0" ?>
<robot name="Robot">
  <!--Generated by RobotCAD, a ROS Workbench for FreeCAD (https://github.com/drfenixion/freecad.robotcad)-->
  <link name="l_car_frame001">
    <visual>
      <!--car_frame001/car_frame001.Body.-->
      <origin rpy="0 0 0" xyz="0.1 0.1 0.1"/>
      <geometry>
        <mesh filename="package://diff_drive/meshes/diffdrive_body_sugjof.dae"/>
      </geometry>
    </visual>
    <collision>
      <origin rpy="0 0 0" xyz="0.1 0.1 0.1"/>
      <geometry>
        <box size="0.5 1.175 0.3"/>  <!-- Approximate dimensions -->
      </geometry>
    </collision>

    <inertial>
      <mass value="186.825"/>
      <origin rpy="0 0 0" xyz="0.1 0.1 0.25"/>
      <inertia ixx="22.895792968751056" ixy="-3e-16" ixz="-1e-16" iyy="5.29337500000106" iyz="-0.0" izz="25.386792968751056"/>
    </inertial>
  </link>



  <link name="l_left_front_wheel001">
    <visual>
      <!--left_front_wheel001/left_front_wheel001.Body001.-->
      <origin rpy="0 0 0" xyz="0.0 0.0 0.0"/>
      <geometry>
        <mesh filename="package://diff_drive/meshes/diffdrive_body001_awhmdt.dae"/>
      </geometry>
    </visual>
    <collision>
      <!--col__l_left_front_wheel001__col_left_front_wheel__BoundCylinder/col_left_front_wheel__BoundCylinder.-->
      <origin rpy="1.5707963267948963 0 0" xyz="0.0 0.01 0.0"/>
      <geometry>
        <cylinder length="0.02" radius="0.2"/>
      </geometry>
    </collision>
    <inertial>
      <mass value="2.6640705702441454"/>
      <origin rpy="0 0 0" xyz="0.0 0.01 0.0"/>
      <inertia ixx="0.0267295080558428" ixy="0.0" ixz="0.0" iyy="0.0532814114059431" iyz="-0.0" izz="0.0267295080558433"/>
    </inertial>
  </link>



  <link name="l_left_back_wheel001">
    <visual>
      <!--left_back_wheel001/left_back_wheel001.Body002.-->
      <origin rpy="0 0 0" xyz="0.0 0.0 0.0"/>
      <geometry>
        <mesh filename="package://diff_drive/meshes/diffdrive_body002_5eqtna.dae"/>
      </geometry>
    </visual>
    <collision>
      <!--col__l_left_back_wheel001__col_left_back_wheel__BoundCylinder/col_left_back_wheel__BoundCylinder.-->
      <origin rpy="1.5707963267948968 0 0" xyz="0.0 0.01 0.0"/>
      <geometry>
        <cylinder length="0.02" radius="0.2"/>
      </geometry>
    </collision>
    <inertial>
      <mass value="2.6640705702441445"/>
      <origin rpy="0 0 0" xyz="0.0 0.01 0.0"/>
      <inertia ixx="0.0267295080558428" ixy="0.0" ixz="-0.0" iyy="0.0532814114059431" iyz="0.0" izz="0.0267295080558433"/>
    </inertial>
  </link>




  <link name="l_right_front_wheel001">
    <visual>
      <!--right_front_wheel001/right_front_wheel001.Body003.-->
      <origin rpy="0 0 0" xyz="0.0 0.0 0.0"/>
      <geometry>
        <mesh filename="package://diff_drive/meshes/diffdrive_body003_hnqjn0.dae"/>
      </geometry>
    </visual>
    <collision>
      <!--col__l_right_front_wheel001__col_right_front_wheel__BoundCylinder/col_right_front_wheel__BoundCylinder.-->
      <origin rpy="-1.570796326794897 0 0" xyz="0.0 -0.01 0.0"/>
      <geometry>
        <cylinder length="0.02" radius="0.2"/>
      </geometry>
    </collision>
    <inertial>
      <mass value="2.664070570244145"/>
      <origin rpy="0 0 0" xyz="0.0 -0.01 0.0"/>
      <inertia ixx="0.0267295080558435" ixy="4.4763163e-09" ixz="4e-16" iyy="0.0532814114059423" iyz="2.3212409e-09" izz="0.0267295080558435"/>
    </inertial>
  </link>



  <link name="l_right_back_wheel001">
    <visual>
      <!--right_back_wheel001/right_back_wheel001.Body004.-->
      <origin rpy="0 0 0" xyz="0.0 0.0 0.0"/>
      <geometry>
        <mesh filename="package://diff_drive/meshes/diffdrive_body004_q8sv7a.dae"/>
      </geometry>
    </visual>
    <collision>
      <!--col__l_right_back_wheel001__col_right_back_wheel__BoundCylinder/col_right_back_wheel__BoundCylinder.-->
      <origin rpy="-1.5707963267948963 0 0" xyz="0.0 -0.01 0.002"/>
      <geometry>
        <cylinder length="0.02" radius="0.2"/>
      </geometry>
    </collision>
    <inertial>
      <mass value="2.6640705702441445"/>
      <origin rpy="0 0 0" xyz="0.0 -0.1 0.0"/>
      <inertia ixx="0.0532814114059431" ixy="-0.0" ixz="0.0" iyy="0.0267295080558428" iyz="0.0" izz="0.0267295080558433"/>
    </inertial>
  </link>



  <joint name="l_car_frame001__to__l_left_front_wheel001" type="continuous">
    <parent link="l_car_frame001"/>
    <child link="l_left_front_wheel001"/>
    <origin rpy="0 0 1.5707963267948968" xyz="-0.15 0.6875 0.1"/>
    <axis xyz="0 1 0"/>
  </joint>


  <joint name="l_car_frame001__to__l_left_back_wheel001" type="continuous">
    <parent link="l_car_frame001"/>
    <child link="l_left_back_wheel001"/>
    <origin rpy="0 0 1.5707963267948961" xyz="-0.15 -0.4875 0.1"/>
    <axis xyz="0 1 0"/>
  </joint>


  <joint name="l_car_frame001__to__l_right_front_wheel001" type="continuous">
    <parent link="l_car_frame001"/>
    <child link="l_right_front_wheel001"/>
    <origin rpy="0 0 1.5707963267948961" xyz="0.35 0.6875 0.1"/>
    <axis xyz="0 -1 0"/>
  </joint>


  <joint name="l_car_frame001__to__l_right_back_wheel001" type="continuous">
    <parent link="l_car_frame001"/>
    <child link="l_right_back_wheel001"/>
    <origin rpy="0 0 1.5707963267948961" xyz="0.37 -0.4875 0.1"/>
    <axis xyz="0 -1 0"/>
  </joint>



    <!-- Gazebo ros2_control plugin -->
  <ros2_control name="MockHardware" type="system">
    <hardware>
      <plugin>mock_components/GenericSystem</plugin>
      <param name="mock_sensor_commands">false</param>
      <param name="state_following_offset">0.0</param>
    </hardware>
    
    <!-- Left wheels -->
    <joint name="l_car_frame001__to__l_left_front_wheel001">
      <command_interface name="velocity">
        <param name="min">-10</param>
        <param name="max">10</param>
      </command_interface>
      <state_interface name="velocity"/>
      <state_interface name="position"/>
    </joint>
    
    <joint name="l_car_frame001__to__l_left_back_wheel001">
      <command_interface name="velocity">
        <param name="min">-10</param>
        <param name="max">10</param>
      </command_interface>
      <state_interface name="velocity"/>
      <state_interface name="position"/>
    </joint>
    
    <!-- Right wheels -->
    <joint name="l_car_frame001__to__l_right_front_wheel001">
      <command_interface name="velocity">
        <param name="min">-10</param>
        <param name="max">10</param>
      </command_interface>
      <state_interface name="velocity"/>
      <state_interface name="position"/>
    </joint>
    
    <joint name="l_car_frame001__to__l_right_back_wheel001">
      <command_interface name="velocity">
        <param name="min">-10</param>
        <param name="max">10</param>
      </command_interface>
      <state_interface name="velocity"/>
      <state_interface name="position"/>
    </joint>
  </ros2_control>

  <!-- Gazebo ros2_control plugin
  <gazebo>
    <plugin filename="libgz_ros2_control-system.so" name="gz_ros2_control::GazeboSimROS2ControlPlugin">
      <parameters>$(find diff_drive)/overcross/Robot_controllers.yaml</parameters>
    </plugin>
  </gazebo> -->

</robot>
